<?xml version="1.0"?>
<robot xmlns:xacro="http://www.ros.org/wiki/xacro" name="otto">
    <!-- Declare PI -->
    <xacro:property name="PI" value="3.14159265359"/>
    <xacro:include filename="gazebo.xacro"/>

    <!-- <link name="world"></link>

    <joint name="base_joint" type="fixed">
      <origin xyz="0.0 0.0 0.5" rpy="0.0 0.0 0.0"/>
      <parent link="world"/>
      <child link="base_link"/>        
    </joint> -->

    <!-- Base Link -->
    <link name="base_link">
        <inertial>
          <origin xyz="-0.02195199 0.0 0.0" rpy="0 0 0"/>
          <mass value="3.00"/>
          <inertia ixx="14584893e-9" ixy="0.0" ixz="0.0"
                   iyx="0.0" iyy="16663530e-9" iyz="0.0"
                   izx="0.0" izy="0.0" izz="20218332e-9" />
        </inertial>
        
        <visual>
            <origin rpy="0.0 0.0 0.0" xyz="0.0 0.0 0.0"/>
            <geometry>
              <mesh filename='file:///$(find otto_simulation)/meshes/Body.STL' scale="0.001 0.001 0.001"/>
            </geometry>
        </visual>

        <collision>
            <origin rpy="0.0 0.0 0.0" xyz="0.0 0.0 0.0"/>
            <geometry>
                <box size="0.22 0.19 0.15"/> 
            </geometry>
        </collision>
    </link>



    <joint name="imu_joint" type="fixed">
      <axis xyz="0 1 0" />
      <parent link="base_link"/>
      <child link="imu_link"/>
    </joint>

    <link name="imu_link">
      <inertial>
        <mass value="1e-5" />
        <origin xyz="0 0 0" rpy="0 0 0"/>
        <inertia ixx="1e-6" ixy="0" ixz="0" iyy="1e-6" iyz="0" izz="1e-6" />
      </inertial>
    </link>

    <!-- Hip Motor Left -->
    <link name="hip_motorL">
      <inertial>
        <origin xyz="0.0 0.0 0.0" rpy="0 0 0"/>
        <mass value="0.11255"/>
        <inertia ixx="0.090104e-3" ixy="0.000735e-3" ixz="0.00035172e-3"
                 iyx="0.000735e-3" iyy="0.074462e-3" iyz="0.000140e-3"
                 izx="0.000351e-3" izy="0.000140e-3" izz="0.091432e-3" />
      </inertial>
      
      <visual>
          <origin rpy="0.0 0.0 0.0" xyz="0.0 0.0 0.0"/> 
          <geometry>
            <mesh filename='file:///$(find otto_simulation)/meshes/CyberGearmotor.STL' scale="0.001 0.001 0.001"/>
          </geometry>
      </visual>
    </link>

    <!-- Knee Motor Left -->
    <link name="knee_motorL">
      <inertial>
        <origin xyz="0.0 0.0 0.0" rpy="0 0 0"/>
        <mass value="0.11255"/>
        <inertia ixx="0.090104e-3" ixy="0.000735e-3" ixz="0.00035172e-3"
                 iyx="0.000735e-3" iyy="0.074462e-3" iyz="0.000140e-3"
                 izx="0.000351e-3" izy="0.000140e-3" izz="0.091432e-3" />
      </inertial>
      <visual>
          <origin rpy="0.0 0.0 0.0" xyz="0.0 0.0 0.0"/> 
          <geometry>
            <mesh filename='file:///$(find otto_simulation)/meshes/CyberGearmotor.STL' scale="0.001 0.001 0.001"/>
          </geometry>
      </visual>
    </link>

    <!-- Hip link Left -->
    <link name="hip_linkL">
      <inertial>
        <origin xyz="0.0 0.0 0.0" rpy="0 0 0"/>
        <mass value="0.036"/>
        <inertia ixx="0.038283e-3" ixy="-0.00189e-3" ixz="-0.020858e-3"
                 iyx="0.00189e-3" iyy="0.066365e-3" iyz="0.0021110e-3"
                 izx="0.0208580e-3" izy="0.0021110e-3" izz="0.030274e-3" />
      </inertial>
      <visual>
          <origin rpy="0.0 0.0 0.0" xyz="0.0 0.0 0.0"/> 
          <geometry>
            <mesh filename='file:///$(find otto_simulation)/meshes/link1.STL' scale="0.001 0.001 0.001"/>
          </geometry>
      </visual>
    </link> 

    <!-- Knee link Left -->
    <link name="knee_linkL">
      <inertial>
        <origin xyz="0.0 0.0 0.0" rpy="0 0 0"/>
        <mass value="0.09629"/>
        <inertia ixx="808404e-9" iyy="1510417e-9" izz="743050e-9" ixy="0.0" iyz="0.0" ixz="0.0"/>
      </inertial>
      <visual>
          <origin rpy="0.0 0.0 0.0" xyz="0.0 0.0 0.0"/> 
          <geometry>
            <mesh filename='file:///$(find otto_simulation)/meshes/link2.STL' scale="0.001 0.001 0.001"/>
          </geometry>
      </visual>
    </link> 

    <!-- Leg link Left -->
    <link name="leg_linkL">
      <inertial>
        <origin xyz="0.0 0.0 0.0" rpy="0 0 0"/>
        <mass value="0.08537"/>
        <inertia ixx="421600e-9" iyy="982737e-9" izz="566988e-9" ixy="0.0" iyz="0.0" ixz="0.0"/>
      </inertial>
      <visual>
          <origin rpy="0.0 0.0 0.0" xyz="0.0 0.0 0.0"/> 
          <geometry>
            <mesh filename='file:///$(find otto_simulation)/meshes/link4.STL' scale="0.001 0.001 0.001"/>
          </geometry>
      </visual>
      <collision>
        <origin rpy="0.0 0.0 0.0" xyz="-0.05656 0.00 0.05656"/>
        <geometry>
            <sphere radius="0.01"/>
        </geometry>
      </collision>

    </link> 

    <!-- wheel link Left -->
    <link name="wheel_linkL">
      <inertial>
        <origin xyz="0.0 0.0 0.0" rpy="0 0 0"/>
        <mass value="0.51691"/>
        <inertia ixx="1.717624e-3" ixy="0.000049e-3" ixz="-0.000006e-3"
                 iyx="0.000049e-3" iyy="2.388020e-3" iyz="0.000004e-3"
                 izx="-0.000006e-3" izy="-0.000015e-3" izz="1.717603e-3" />
      </inertial>

      <visual>
          <origin rpy="${PI} 0.0 0.0" xyz="0.0 0.0 0.0"/> 
          <geometry>
            <mesh filename='file:///$(find otto_simulation)/meshes/ODriveBotwheel.STL' scale="0.001 0.001 0.001"/>
          </geometry>
      </visual>
      <collision>
        <origin rpy="${PI/2} 0.0 0.0" xyz="0.0 0.02 0.0"/>
        <geometry>
            <cylinder radius="0.086" length="0.04416"/> 
        </geometry>
      </collision>
      
    </link> 

    <joint name="hip_jointL" type="fixed">
      <parent link="base_link"/>
      <child link="hip_motorL"/>
        <origin rpy="0.0 0.0 0.0" xyz="-0.03 0.06 0.0"/>
        <axis xyz="0.0 1.0 0.0"/>
        <!-- <limit effort="8.0"="50.0" lower="${-PI}" upper="${PI}" velocity="30"/> -->
    </joint>

    <joint name="hip_motorL_to_knee_motorL" type="fixed">
      <parent link="hip_motorL"/>
      <child link="knee_motorL"/>
      <origin rpy="0.0 0.0 0.0" xyz="0.0 0.05 0.0"/>
    </joint>

    <joint name="hip_motorL_to_hip_linkL" type="fixed">
      <parent link="knee_motorL"/>
      <child link="hip_linkL"/>
      <origin rpy="0.0 0.0 0.0" xyz="0.0 0.035 0.0"/>
    </joint>

    <joint name="knee_jointL" type="continuous">
      <parent link="knee_motorL"/>
      <child link="knee_linkL"/>
      <origin rpy="0.0 0.0 0.0" xyz="0.0 0.055 0.0"/>
      <axis xyz="0.0 1.0 0.0"/>
      <dynamics damping="0.22" friction="0.0"/>
      <limit effort="8.0" lower="${-PI}" upper="${PI}" velocity="30"/>
    </joint>

    <joint name="virtualhip_jointL" type="continuous">
      <parent link="knee_linkL"/>
      <child link="leg_linkL"/>
      <origin rpy="0.0 0.0 0.0" xyz="-0.1414 -0.05 -0.1414"/>
      <axis xyz="0.0 1.0 0.0"/>
      <dynamics damping="0.22" friction="0.0"/>
      <limit effort="8.0" lower="${-PI}" upper="${PI}" velocity="30"/>
    </joint>

    <joint name="wheel_jointL" type="continuous">
      <parent link="leg_linkL"/>
      <child link="wheel_linkL"/>
      <origin rpy="0.0 0.0 0.0" xyz="0.1414 0.02 -0.1414"/>
      <axis xyz="0.0 1.0 0.0"/>
      <dynamics damping="0.01" friction="0.01"/>
      <limit effort="300.0" velocity="50"/>
    </joint>

    <!-- Right Side -->

    <!-- Hip Motor Right -->
    <link name="hip_motorR">
      <inertial>
        <origin xyz="0.0 0.0 0.0" rpy="0 0 0"/>
        <mass value="0.11255"/>
        <inertia ixx="0.090104e-3" ixy="0.000735e-3" ixz="0.00035172e-3"
                 iyx="0.000735e-3" iyy="0.074462e-3" iyz="0.000140e-3"
                 izx="0.000351e-3" izy="0.000140e-3" izz="0.091432e-3" />
      </inertial>
      <visual>
          <origin rpy="${PI} 0.0 0.0" xyz="0.0 0.0 0.0"/> 
          <geometry>
            <mesh filename='file:///$(find otto_simulation)/meshes/CyberGearmotor.STL' scale="0.001 0.001 0.001"/>
          </geometry>
      </visual>
    </link>

    <!-- Knee Motor Right -->
    <link name="knee_motorR">
      <inertial>
        <origin xyz="0.0 0.0 0.0" rpy="0 0 0"/>
        <mass value="0.11255"/>
        <inertia ixx="0.090104e-3" ixy="0.000735e-3" ixz="0.00035172e-3"
                 iyx="0.000735e-3" iyy="0.074462e-3" iyz="0.000140e-3"
                 izx="0.000351e-3" izy="0.000140e-3" izz="0.091432e-3" />
      </inertial>
      <visual>
          <origin rpy="${PI} 0.0 0.0" xyz="0.0 0.0 0.0"/> 
          <geometry>
            <mesh filename='file:///$(find otto_simulation)/meshes/CyberGearmotor.STL' scale="0.001 0.001 0.001"/>
          </geometry>
      </visual>

    </link>

    <!-- Hip link Right -->
    <link name="hip_linkR">
      <inertial>
        <origin xyz="0.0 0.0 0.0" rpy="0 0 0"/>
        <mass value="0.036"/>
        <inertia ixx="0.038283e-3" ixy="0.00189e-3" ixz="-0.020858e-3"
                 iyx="0.00189e-3" iyy="0.066365e-3" iyz="-0.0021110e-3"
                 izx="-0.0208580e-3" izy="-0.0021110e-3" izz="0.030274e-3" />
      </inertial>
      <visual>
          <origin rpy="0.0 0.0 0.0" xyz="0.0 0.0 0.0"/> 
          <geometry>
            <mesh filename='file:///$(find otto_simulation)/meshes/link1R.STL' scale="0.001 0.001 0.001"/>
          </geometry>
      </visual>
    </link>

    <!-- Knee link Right -->
    <link name="knee_linkR">
      <inertial>
        <origin xyz="0.0 0.0 0.0" rpy="0 0 0"/>
        <mass value="0.09629"/>
        <inertia ixx="808404e-9" iyy="1510417e-9" izz="743050e-9" ixy="0.0" iyz="0.0" ixz="0.0"/>
      </inertial>
      <visual>
          <origin rpy="0.0 0.0 0.0" xyz="0.0 0.0 0.0"/> 
          <geometry>
            <mesh filename='file:///$(find otto_simulation)/meshes/link2R.STL' scale="0.001 0.001 0.001"/>
          </geometry>
      </visual>
    </link> 

    <!-- Leg link Right -->
    <link name="leg_linkR">
      <inertial>
        <origin xyz="0.0 0.0 0.0" rpy="0 0 0"/>
        <mass value="0.08537"/>
        <inertia ixx="421600e-9" iyy="982737e-9" izz="566988e-9" ixy="0.0" iyz="0.0" ixz="0.0"/>
      </inertial>
      <visual>
          <origin rpy="0.0 0.0 0.0" xyz="0.0 0.0 0.0"/> 
          <geometry>
            <mesh filename='file:///$(find otto_simulation)/meshes/link4R.STL' scale="0.001 0.001 0.001"/>
          </geometry>
      </visual>
      <collision>
        <origin rpy="0.0 0.0 0.0" xyz="-0.05656 0.00 0.05656"/>
        <geometry>
            <sphere radius="0.01"/>
        </geometry>
      </collision>
    </link> 

    <!-- wheel link Right -->
    <link name="wheel_linkR">
      <inertial>
        <origin xyz="0.0 0.0 0.0" rpy="0 0 0"/>
        <mass value="0.51691"/>
        <inertia ixx="1.717624e-3" ixy="0.000049e-3" ixz="-0.000006e-3"
                 iyx="0.000049e-3" iyy="2.388020e-3" iyz="0.000004e-3"
                 izx="-0.000006e-3" izy="-0.000015e-3" izz="1.717603e-3" />
      </inertial>

      <visual>
          <origin rpy="0.0 0.0 0.0" xyz="0.0 0.0 0.0"/> 
          <geometry>
            <mesh filename='file:///$(find otto_simulation)/meshes/ODriveBotwheel.STL' scale="0.001 0.001 0.001"/>
          </geometry>
      </visual>
      <collision>
        <origin rpy="${PI/2} 0.0 0.0" xyz="0.0 -0.02 0.0"/>
        <geometry>
            <cylinder radius="0.086" length="0.04416"/> 
        </geometry>
      </collision>
    </link> 

    <joint name="hip_jointR" type="fixed">
      <parent link="base_link"/>
      <child link="hip_motorR"/>
        <origin rpy="0.0 0.0 0.0" xyz="-0.03 -0.06 0.0"/>
        <axis xyz="0.0 1.0 0.0"/>
        <!-- <limit effort="5.0" lower="${-PI}" upper="${PI}" velocity="30"/> -->
      </joint>


    <joint name="hip_motorR_to_knee_motorR" type="fixed">
      <parent link="hip_motorR"/>
      <child link="knee_motorR"/>
      <origin rpy="0.0 0.0 0.0" xyz="0.0 -0.05 0.0"/>
    </joint>

    <joint name="hip_motorR_to_hip_linkR" type="fixed">
      <parent link="knee_motorR"/>
      <child link="hip_linkR"/>
      <origin rpy="0.0 0.0 0.0" xyz="0.0 -0.035 0.0"/>
    </joint>

    <joint name="knee_jointR" type="continuous">
      <parent link="knee_motorR"/>
      <child link="knee_linkR"/>
      <origin rpy="0.0 0.0 0.0" xyz="0.0 -0.055 0.0"/>
      <axis xyz="0.0 1.0 0.0"/>
      <dynamics damping="0.22" friction="0.0"/>
      <limit effort="8.0" lower="${-PI}" upper="${PI}" velocity="30"/>
    </joint>

    <joint name="virtualhip_jointR" type="continuous">
      <parent link="knee_linkR"/>
      <child link="leg_linkR"/>
      <origin rpy="0.0 0.0 0.0" xyz="-0.1414 0.05 -0.1414"/>
      <axis xyz="0.0 1.0 0.0"/>
      <dynamics damping="0.22" friction="0.0"/>
      <limit effort="8.0" lower="${-PI}" upper="${PI}" velocity="30"/>
    </joint>

    <joint name="wheel_jointR" type="continuous">
      <parent link="leg_linkR"/>
      <child link="wheel_linkR"/>
      <origin rpy="0.0 0.0 0.0" xyz="0.1414 -0.02 -0.1414"/>
      <axis xyz="0.0 1.0 0.0"/>
      <dynamics damping="0.01" friction="0.01"/>
      <limit effort="300.0" velocity="50"/>
    </joint>

    <gazebo reference="imu_link">
      <gravity>true</gravity>
      <sensor name="imu_sensor" type="imu">
        <always_on>true</always_on>
        <update_rate>500.0</update_rate>
        <visualize>true</visualize>
        <plugin filename="libgazebo_ros_imu_sensor.so" name="imu_plugin">
          <topicName>otto_imu</topicName>
          <bodyName>imu_link</bodyName>
          <updateRateHZ>200.0</updateRateHZ>
          <gaussianNoise>0.0</gaussianNoise>
          <xyzOffset>0 0 0</xyzOffset>
          <rpyOffset>0 0 0</rpyOffset>
          <frameName>imu_link</frameName>
          <initialOrientationAsReference>false</initialOrientationAsReference>
        </plugin>
        <pose>0 0 0 0 0 0</pose>
      </sensor>
    </gazebo>
  
</robot>