<?xml version="1.0"?>
<robot xmlns:xacro="http://www.ros.org/wiki/xacro" name="otto">
    <!-- Declare PI -->
    <xacro:property name="PI" value="3.14159265359"/>
    <xacro:include filename="gazebo.xacro"/>
    <link name="world"></link>

    <joint name="base_joint" type="fixed">
      <origin xyz="0 0 0.4" rpy="0 0 0"/>
      <parent link="world"/>
      <child link="base_link"/>        
    </joint>

    <!-- Base Link -->
    <link name="base_link">
        <inertial>
          <origin xyz="-0.03 0.0 0.0" rpy="0 0 0"/>
          <mass value="5.0"/>
          <inertia ixx="0.553912" iyy="1.227224" izz="1.101448" ixy="-0.0" iyz="-0.0" ixz="0.005005"/>
        </inertial>
        
        <visual>
            <origin rpy="0.0 0.0 0.0" xyz="0.0 0.0 0.0"/>
            <geometry>
              <mesh filename='file:///$(find otto_simulation)/meshes/Body.STL' scale="0.001 0.001 0.001"/>
            </geometry>
        </visual>

        <collision>
            <origin rpy="0.0 0.0 0.0" xyz="0.0 0.0 0.0"/>
            <geometry>
                <box size="0.20 0.19 0.15"/> 
            </geometry>
        </collision>
    </link>

    <!-- Hip Motor Left -->
    <link name="hip_motorL">
      <inertial>
        <origin xyz="0.00 0.0 0.0" rpy="0 0 0"/>
        <mass value="2e-6"/>
        <inertia ixx="1.1e-9" iyy="1.1e-9" izz="1.1e-9" ixy="0.0" iyz="0.0" ixz="0.0"/>
      </inertial>
      <visual>
          <origin rpy="0.0 0.0 0.0" xyz="0.0 0.0 0.0"/> 
          <geometry>
            <mesh filename='file:///$(find otto_simulation)/meshes/CyberGearmotor.STL' scale="0.001 0.001 0.001"/>
          </geometry>
      </visual>
    </link>

    <!-- Knee Motor Left -->
    <link name="knee_motorL">
      <inertial>
        <origin xyz="0.00 0.0 0.0" rpy="0 0 0"/>
        <mass value="2e-6"/>
        <inertia ixx="1.1e-9" iyy="1.1e-9" izz="1.1e-9" ixy="0.0" iyz="0.0" ixz="0.0"/>
      </inertial>
      <visual>
          <origin rpy="0.0 0.0 0.0" xyz="0.0 0.0 0.0"/> 
          <geometry>
            <mesh filename='file:///$(find otto_simulation)/meshes/CyberGearmotor.STL' scale="0.001 0.001 0.001"/>
          </geometry>
      </visual>
    </link>

    <!-- Hip link Left -->
    <link name="hip_linkL">
      <inertial>
        <origin xyz="0.00 0.0 0.0" rpy="0 0 0"/>
        <mass value="2e-6"/>
        <inertia ixx="1.1e-9" iyy="1.1e-9" izz="1.1e-9" ixy="0.0" iyz="0.0" ixz="0.0"/>
      </inertial>
      <visual>
          <origin rpy="0.0 0.0 0.0" xyz="0.0 0.0 0.0"/> 
          <geometry>
            <mesh filename='file:///$(find otto_simulation)/meshes/link1.STL' scale="0.001 0.001 0.001"/>
          </geometry>
      </visual>
    </link> 

    <!-- Knee link Left -->
    <link name="knee_linkL">
      <inertial>
        <origin xyz="0.00 0.0 0.0" rpy="0 0 0"/>
        <mass value="2e-6"/>
        <inertia ixx="1.1e-9" iyy="1.1e-9" izz="1.1e-9" ixy="0.0" iyz="0.0" ixz="0.0"/>
      </inertial>
      <visual>
          <origin rpy="0.0 0.0 0.0" xyz="0.0 0.0 0.0"/> 
          <geometry>
            <mesh filename='file:///$(find otto_simulation)/meshes/link2.STL' scale="0.001 0.001 0.001"/>
          </geometry>
      </visual>
    </link> 

    <!-- Leg link Left -->
    <link name="leg_linkL">
      <inertial>
        <origin xyz="0.00 0.0 0.0" rpy="0 0 0"/>
        <mass value="2e-6"/>
        <inertia ixx="1.1e-9" iyy="1.1e-9" izz="1.1e-9" ixy="0.0" iyz="0.0" ixz="0.0"/>
      </inertial>
      <visual>
          <origin rpy="0.0 0.0 0.0" xyz="0.0 0.0 0.0"/> 
          <geometry>
            <mesh filename='file:///$(find otto_simulation)/meshes/link4.STL' scale="0.001 0.001 0.001"/>
          </geometry>
      </visual>
    </link> 

    <!-- wheel link Left -->
    <link name="wheel_linkL">
      <inertial>
        <origin xyz="0.0 0.02 0.0" rpy="0 0 0"/>
        <mass value="1"/>
        <inertia ixx="0.025678" iyy="0.046537" izz="0.025678" ixy="-0.0" iyz="0.0" ixz="0.0"/>
      </inertial>

      <visual>
          <origin rpy="${PI} 0.0 0.0" xyz="0.0 0.0 0.0"/> 
          <geometry>
            <mesh filename='file:///$(find otto_simulation)/meshes/ODriveBotwheel.STL' scale="0.001 0.001 0.001"/>
          </geometry>
      </visual>
      <collision>
        <origin rpy="${PI/2} 0.0 0.0" xyz="0.0 0.02 0.0"/>
        <geometry>
            <cylinder radius="0.086" length="0.04416"/> 
        </geometry>
      </collision>
      
    </link> 

    <joint name="hip_jointL" type="continuous">
      <parent link="base_link"/>
      <child link="hip_motorL"/>
        <origin rpy="0.0 0.0 0.0" xyz="-0.03 0.06 0.0"/>
        <axis xyz="0.0 1.0 0.0"/>
    </joint>

    <joint name="hip_motorL_to_knee_motorL" type="fixed">
      <parent link="hip_motorL"/>
      <child link="knee_motorL"/>
      <origin rpy="0.0 0.0 0.0" xyz="0.0 0.05 0.0"/>
    </joint>

    <joint name="hip_motorL_to_hip_linkL" type="fixed">
      <parent link="knee_motorL"/>
      <child link="hip_linkL"/>
      <origin rpy="0.0 0.0 0.0" xyz="0.0 0.035 0.0"/>
    </joint>

    <joint name="knee_jointL" type="continuous">
      <parent link="knee_motorL"/>
      <child link="knee_linkL"/>
      <origin rpy="0.0 0.0 0.0" xyz="0.0 0.055 0.0"/>
      <axis xyz="0.0 1.0 0.0"/>
    </joint>

    <joint name="virtualhip_jointL" type="continuous">
      <parent link="knee_linkL"/>
      <child link="leg_linkL"/>
      <origin rpy="0.0 0.0 0.0" xyz="-0.1414 -0.05 -0.1414"/>
      <axis xyz="0.0 1.0 0.0"/>
    </joint>

    <joint name="wheel_jointL" type="continuous">
      <parent link="leg_linkL"/>
      <child link="wheel_linkL"/>
      <origin rpy="0.0 0.0 0.0" xyz="0.1414 0.02 -0.1414"/>
      <axis xyz="0.0 1.0 0.0"/>
    </joint>

    <!-- Right Side -->

    <!-- Hip Motor Right -->
    <link name="hip_motorR">
      <inertial>
        <origin xyz="0.00 0.0 0.0" rpy="0 0 0"/>
        <mass value="2e-6"/>
        <inertia ixx="1.1e-9" iyy="1.1e-9" izz="1.1e-9" ixy="0.0" iyz="0.0" ixz="0.0"/>
      </inertial>
      <visual>
          <origin rpy="${PI} 0.0 0.0" xyz="0.0 0.0 0.0"/> 
          <geometry>
            <mesh filename='file:///$(find otto_simulation)/meshes/CyberGearmotor.STL' scale="0.001 0.001 0.001"/>
          </geometry>
      </visual>
    </link>

    <!-- Knee Motor Right -->
    <link name="knee_motorR">
      <inertial>
        <origin xyz="0.00 0.0 0.0" rpy="0 0 0"/>
        <mass value="2e-6"/>
        <inertia ixx="1.1e-9" iyy="1.1e-9" izz="1.1e-9" ixy="0.0" iyz="0.0" ixz="0.0"/>
      </inertial>
      <visual>
          <origin rpy="${PI} 0.0 0.0" xyz="0.0 0.0 0.0"/> 
          <geometry>
            <mesh filename='file:///$(find otto_simulation)/meshes/CyberGearmotor.STL' scale="0.001 0.001 0.001"/>
          </geometry>
      </visual>

    </link>

    <!-- Hip link Right -->
    <link name="hip_linkR">
      <inertial>
        <origin xyz="0.00 0.0 0.0" rpy="0 0 0"/>
        <mass value="2e-6"/>
        <inertia ixx="1.1e-9" iyy="1.1e-9" izz="1.1e-9" ixy="0.0" iyz="0.0" ixz="0.0"/>
      </inertial>
      <visual>
          <origin rpy="0.0 0.0 0.0" xyz="0.0 0.0 0.0"/> 
          <geometry>
            <mesh filename='file:///$(find otto_simulation)/meshes/link1R.STL' scale="0.001 0.001 0.001"/>
          </geometry>
      </visual>
    </link> 

    <!-- Knee link Right -->
    <link name="knee_linkR">
      <inertial>
        <origin xyz="0.00 0.0 0.0" rpy="0 0 0"/>
        <mass value="2e-6"/>
        <inertia ixx="1.1e-9" iyy="1.1e-9" izz="1.1e-9" ixy="0.0" iyz="0.0" ixz="0.0"/>
      </inertial>
      <visual>
          <origin rpy="0.0 0.0 0.0" xyz="0.0 0.0 0.0"/> 
          <geometry>
            <mesh filename='file:///$(find otto_simulation)/meshes/link2R.STL' scale="0.001 0.001 0.001"/>
          </geometry>
      </visual>
    </link> 

    <!-- Leg link Right -->
    <link name="leg_linkR">
      <inertial>
        <origin xyz="0.00 0.0 0.0" rpy="0 0 0"/>
        <mass value="2e-6"/>
        <inertia ixx="1.1e-9" iyy="1.1e-9" izz="1.1e-9" ixy="0.0" iyz="0.0" ixz="0.0"/>
      </inertial>
      <visual>
          <origin rpy="0.0 0.0 0.0" xyz="0.0 0.0 0.0"/> 
          <geometry>
            <mesh filename='file:///$(find otto_simulation)/meshes/link4R.STL' scale="0.001 0.001 0.001"/>
          </geometry>
      </visual>
    </link> 

    <!-- wheel link Right -->
    <link name="wheel_linkR">
      <inertial>
        <origin xyz="0.0 -0.02 0.0" rpy="0 0 0"/>
        <mass value="1.0"/>
        <inertia ixx="0.025678" iyy="0.046537" izz="0.025678" ixy="-0.0" iyz="0.0" ixz="0.0"/>
      </inertial>

      <visual>
          <origin rpy="0.0 0.0 0.0" xyz="0.0 0.0 0.0"/> 
          <geometry>
            <mesh filename='file:///$(find otto_simulation)/meshes/ODriveBotwheel.STL' scale="0.001 0.001 0.001"/>
          </geometry>
      </visual>
      <collision>
        <origin rpy="${PI/2} 0.0 0.0" xyz="0.0 -0.02 0.0"/>
        <geometry>
            <cylinder radius="0.086" length="0.04416"/> 
        </geometry>
      </collision>
    </link> 

    <joint name="hip_jointR" type="continuous">
      <parent link="base_link"/>
      <child link="hip_motorR"/>
        <origin rpy="0.0 0.0 0.0" xyz="-0.03 -0.06 0.0"/>
        <axis xyz="0.0 1.0 0.0"/>
    </joint>


    <joint name="hip_motorR_to_knee_motorR" type="fixed">
      <parent link="hip_motorR"/>
      <child link="knee_motorR"/>
        <origin rpy="0.0 0.0 0.0" xyz="0.0 -0.05 0.0"/>
    </joint>

    <joint name="hip_motorR_to_hip_linkR" type="fixed">
      <parent link="knee_motorR"/>
      <child link="hip_linkR"/>
      <origin rpy="0.0 0.0 0.0" xyz="0.0 -0.035 0.0"/>
    </joint>

    <joint name="knee_jointR" type="continuous">
      <parent link="knee_motorR"/>
      <child link="knee_linkR"/>
      <origin rpy="0.0 0.0 0.0" xyz="0.0 -0.05 0.0"/>
      <axis xyz="0.0 1.0 0.0"/>
    </joint>

    <joint name="virtualhip_jointR" type="continuous">
      <parent link="knee_linkR"/>
      <child link="leg_linkR"/>
      <origin rpy="0.0 0.0 0.0" xyz="-0.1414 0.05 -0.1414"/>
      <axis xyz="0.0 1.0 0.0"/>
    </joint>

    <joint name="wheel_jointR" type="continuous">
      <parent link="leg_linkR"/>
      <child link="wheel_linkR"/>
      <origin rpy="0.0 0.0 0.0" xyz="0.1414 -0.02 -0.1414"/>
      <axis xyz="0.0 1.0 0.0"/>
    </joint>

</robot>
